<?xml version = "1.0"?>
<robot xmlns:xacro="http://www.ros.org/wiki/xacro" name="bobbot">

    <!--(ros2 run joint_state_publisher_gui joint_state_publisher_gui) to edit joint variables-->

    <!--Important: The origin values for joints are wrt frame of parent link. The origin values of link are wrt to their joint. (of which the are child)-->

    <!--xacro properties-->
    <xacro:property name ="base_mass" value ="1.0"/>
    <xacro:property name ="arm_link_1_mass" value = "0.5"/>
    <xacro:property name ="arm_link_2_mass" value = "0.8"/>
    <xacro:property name ="arm_link_3_mass" value = "0.7"/>
    <xacro:property name ="base_link_frame_limit" value = "2.36"/>


    <!--xacro includes-->
    <xacro:include filename = "materials.xacro"/>
    <xacro:include filename = "macros.xacro"/>

    <link name = "dummy_link"></link>

    <link name = "revolve_disc"></link>

    <link name="base_link">
        <visual>
            <material name ="black">
                <color rgba = "0 0 1 1"/>
            </material>
            <origin xyz = "0 0 0" rpy = "0 0 0"/>
            <geometry>
                <box size = "2 1.2 0.5"/>
            </geometry>
        </visual>

        <collision>
            <origin xyz = "0 0 0" rpy = "0 0 0"/>
            <geometry>
                <box size = "2 1.2 0.5"/>
            </geometry> 
        </collision>

        <xacro:Inertial_Box mass = "${base_mass}" x = "2" y = "1.2" z = "0.5"> <!--check with geometery size tag-->
            <origin xyz ="0 0 0" rpy = "0 0 0"/> 
        </xacro:Inertial_Box>
    </link>

    <link name = "arm_link_1">
        <visual>
            <material name = "green"/>
            <origin xyz = "0 0 0.1" rpy = "0 0 0"/>
            <geometry>
                <box size = "0.2 0.2 0.2"/>
            </geometry>
        </visual>

        <collision>
            <origin xyz = "0 0 0.1" rpy = "0 0 0"/>
            <geometry>
                <box size = "0.2 0.2 0.2"/>
            </geometry>
        </collision>

        <xacro:Inertial_Box mass = "${arm_link_1_mass}" x = "0.2" y = "0.2" z = "0.2">
            <origin xyz = "0 0 0.1" rpy = "0 0 0"/>
        </xacro:Inertial_Box>
    </link>

    <link name = "arm_link_2">
        <visual>
            <material name = "red"/>
            <origin xyz = "0.35 0 0.1" rpy = "0 0 0"/>
            <geometry>
                <box size = "0.7 0.2 0.2"/>
            </geometry>
        </visual>

        <collision>
            <origin xyz = "0.35 0 0.1" rpy = "0 0 0"/>
            <geometry>
                <box size = "0.7 0.2 0.2"/>
            </geometry>
        </collision>

        <xacro:Inertial_Box mass = "${arm_link_2_mass}" x = "0.7" y = "0.2" z = "0.2">
            <origin xyz = "0.35 0 0.1" rpy = "0 0 0"/>
        </xacro:Inertial_Box>
    </link>

    <link name = "arm_link_3">
        <visual>
            <material name = "blue"/>
            <origin xyz = "0.2 0 0" rpy = "0 0 0"/>
            <geometry>
                <box size = "0.4 0.2 0.2"/>
            </geometry>
        </visual>

        <collision>
            <origin xyz = "0.2 0 0" rpy = "0 0 0"/>
            <geometry>
                <box size = "0.4 0.2 0.2"/>
            </geometry>
        </collision>

        <xacro:Inertial_Box mass = "${arm_link_3_mass}" x = "0.4" y = "0.2" z = "0.2">
            <origin xyz = "0.2 0 0" rpy = "0 0 0"/>
        </xacro:Inertial_Box>
    </link>



    <!--Whenever turning joints not rendered, set them to fixed and then change back-->

    <joint name = "dummy_joint" type = "fixed">
        <parent link = "dummy_link"/>
        <child link = "base_link"/>
        <origin xyz = "0 0 0" rpy = "0 0 0"/>
    </joint>

    <joint name="revolve_joint" type ="continuous">
        <parent link="revolve_disc"/>
        <child link="arm_link_1"/>
        <origin xyz = "-0.75 0 0.25" rpy = "0 0 0"/>
        <axis xyz = "0 0 1"/>
    </joint>

    <joint name="base_link_frame" type="prismatic">
        <origin xyz="0 0 0" rpy="0 0 0"/>
        <parent link = "base_link"/>
        <child link = "revolve_disc"/>
        <axis xyz="1 0 0"/>
        <limit lower="0" upper="1" velocity="10" effort="100"/> 
    </joint>

    <joint name="frame_1" type="revolute">
        <origin xyz="0.1 0 0.2" rpy="0 0 0"/>
        <parent link="arm_link_1"/>
        <child link="arm_link_2"/>
        <axis xyz="0 -1 0"/>
        <limit lower="0" upper="1.6" velocity="10" effort="100"/> 
    </joint>

    <joint name="frame_2" type="revolute">
        <origin xyz="0.7 0 0.1" rpy="0 0 0"/>
        <parent link="arm_link_2"/>
        <child link="arm_link_3"/>
        <axis xyz="0 0 1"/>
        <limit lower="-1.6" upper="1.6" velocity="10" effort="100"/>  
    </joint>

  
</robot>